[2025-10-08 22:06:40] ============================================================
[2025-10-08 22:06:40] 🚀 Odoo Veri Güncelleme Script'i Başlatıldı
[2025-10-08 22:06:40] ============================================================
[2025-10-08 22:06:40] 🔌 Odoo'ya bağlanılıyor...
[2025-10-08 22:06:40] ❌ HATA: Odoo bağlantı hatası: [SSL: CERTIFICATE_VERIFY_FAILED] certificate verify failed: unable to get local issuer certificate (_ssl.c:1077)
[2025-10-08 22:07:50] ============================================================
[2025-10-08 22:07:50] 🚀 Odoo Veri Güncelleme Script'i Başlatıldı
[2025-10-08 22:07:50] ============================================================
[2025-10-08 22:07:50] 🔌 Odoo'ya bağlanılıyor...
[2025-10-08 22:07:50] 📌 Odoo Versiyonu: 15.0-20240120
[2025-10-08 22:07:50] ❌ HATA: Odoo bağlantı hatası: <Fault 1: 'Traceback (most recent call last):\n  File "/usr/lib/python3/dist-packages/odoo/modules/registry.py", line 61, in __new__\n    return cls.registries[db_name]\n  File "/usr/lib/python3/dist-packages/odoo/tools/func.py", line 71, in wrapper\n    return func(self, *args, **kwargs)\n  File "/usr/lib/python3/dist-packages/odoo/tools/lru.py", line 34, in __getitem__\n    a = self.d[obj]\nKeyError: \'zuhalmuzik\'\n\nDuring handling of the above exception, another exception occurred:\n\nTraceback (most recent call last):\n  File "/usr/lib/python3/dist-packages/odoo/addons/base/controllers/rpc.py", line 93, in xmlrpc_2\n    response = self._xmlrpc(service)\n  File "/usr/lib/python3/dist-packages/odoo/addons/base/controllers/rpc.py", line 73, in _xmlrpc\n    result = dispatch_rpc(service, method, params)\n  File "/usr/lib/python3/dist-packages/odoo/http.py", line 141, in dispatch_rpc\n    result = dispatch(method, params)\n  File "/usr/lib/python3/dist-packages/odoo/service/common.py", line 56, in dispatch\n    return g[exp_method_name](*params)\n  File "/usr/lib/python3/dist-packages/odoo/service/common.py", line 25, in exp_authenticate\n    res_users = odoo.registry(db)[\'res.users\']\n  File "/usr/lib/python3/dist-packages/odoo/__init__.py", line 104, in registry\n    return modules.registry.Registry(database_name)\n  File "/usr/lib/python3/dist-packages/odoo/modules/registry.py", line 63, in __new__\n    return cls.new(db_name)\n  File "/usr/lib/python3/dist-packages/odoo/modules/registry.py", line 75, in new\n    registry.init(db_name)\n  File "/usr/lib/python3/dist-packages/odoo/modules/registry.py", line 151, in init\n    with closing(self.cursor()) as cr:\n  File "/usr/lib/python3/dist-packages/odoo/modules/registry.py", line 728, in cursor\n    return self._db.cursor()\n  File "/usr/lib/python3/dist-packages/odoo/sql_db.py", line 742, in cursor\n    return Cursor(self.__pool, self.__dbname, self.__dsn, serialized=serialized)\n  File "/usr/lib/python3/dist-packages/odoo/sql_db.py", line 259, in __init__\n    self._cnx = pool.borrow(dsn)\n  File "/usr/lib/python3/dist-packages/odoo/sql_db.py", line 603, in _locked\n    return fun(self, *args, **kwargs)\n  File "/usr/lib/python3/dist-packages/odoo/sql_db.py", line 669, in borrow\n    result = psycopg2.connect(\n  File "/usr/lib/python3/dist-packages/psycopg2/__init__.py", line 122, in connect\n    conn = _connect(dsn, connection_factory=connection_factory, **kwasync)\npsycopg2.OperationalError: connection to server on socket "/var/run/postgresql/.s.PGSQL.5432" failed: FATAL:  database "zuhalmuzik" does not exist\n\n'>
[2025-10-17 02:26:25] ============================================================
[2025-10-17 02:26:25] 🚀 Odoo Veri Güncelleme Script'i Başlatıldı
[2025-10-17 02:26:25] ============================================================
[2025-10-17 02:26:25] 🔌 Odoo'ya bağlanılıyor...
[2025-10-17 02:26:25] 📌 Odoo Versiyonu: 15.0-20240120
[2025-10-17 02:26:26] ❌ HATA: Odoo bağlantı hatası: <Fault 1: 'Traceback (most recent call last):\n  File "/usr/lib/python3/dist-packages/odoo/modules/registry.py", line 61, in __new__\n    return cls.registries[db_name]\n  File "/usr/lib/python3/dist-packages/odoo/tools/func.py", line 71, in wrapper\n    return func(self, *args, **kwargs)\n  File "/usr/lib/python3/dist-packages/odoo/tools/lru.py", line 34, in __getitem__\n    a = self.d[obj]\nKeyError: \'zuhalmuzik\'\n\nDuring handling of the above exception, another exception occurred:\n\nTraceback (most recent call last):\n  File "/usr/lib/python3/dist-packages/odoo/addons/base/controllers/rpc.py", line 93, in xmlrpc_2\n    response = self._xmlrpc(service)\n  File "/usr/lib/python3/dist-packages/odoo/addons/base/controllers/rpc.py", line 73, in _xmlrpc\n    result = dispatch_rpc(service, method, params)\n  File "/usr/lib/python3/dist-packages/odoo/http.py", line 141, in dispatch_rpc\n    result = dispatch(method, params)\n  File "/usr/lib/python3/dist-packages/odoo/service/common.py", line 56, in dispatch\n    return g[exp_method_name](*params)\n  File "/usr/lib/python3/dist-packages/odoo/service/common.py", line 25, in exp_authenticate\n    res_users = odoo.registry(db)[\'res.users\']\n  File "/usr/lib/python3/dist-packages/odoo/__init__.py", line 104, in registry\n    return modules.registry.Registry(database_name)\n  File "/usr/lib/python3/dist-packages/odoo/modules/registry.py", line 63, in __new__\n    return cls.new(db_name)\n  File "/usr/lib/python3/dist-packages/odoo/modules/registry.py", line 75, in new\n    registry.init(db_name)\n  File "/usr/lib/python3/dist-packages/odoo/modules/registry.py", line 151, in init\n    with closing(self.cursor()) as cr:\n  File "/usr/lib/python3/dist-packages/odoo/modules/registry.py", line 728, in cursor\n    return self._db.cursor()\n  File "/usr/lib/python3/dist-packages/odoo/sql_db.py", line 742, in cursor\n    return Cursor(self.__pool, self.__dbname, self.__dsn, serialized=serialized)\n  File "/usr/lib/python3/dist-packages/odoo/sql_db.py", line 259, in __init__\n    self._cnx = pool.borrow(dsn)\n  File "/usr/lib/python3/dist-packages/odoo/sql_db.py", line 603, in _locked\n    return fun(self, *args, **kwargs)\n  File "/usr/lib/python3/dist-packages/odoo/sql_db.py", line 669, in borrow\n    result = psycopg2.connect(\n  File "/usr/lib/python3/dist-packages/psycopg2/__init__.py", line 122, in connect\n    conn = _connect(dsn, connection_factory=connection_factory, **kwasync)\npsycopg2.OperationalError: connection to server on socket "/var/run/postgresql/.s.PGSQL.5432" failed: FATAL:  database "zuhalmuzik" does not exist\n\n'>
[2025-10-17 21:20:47] ============================================================
[2025-10-17 21:20:47] 🚀 Odoo Veri Güncelleme Script'i Başlatıldı
[2025-10-17 21:20:47] ============================================================
[2025-10-17 21:20:47] 🔌 Odoo'ya bağlanılıyor...
[2025-10-17 21:20:47] 📌 Odoo Versiyonu: 15.0-20240120
[2025-10-17 21:20:47] ❌ HATA: Odoo bağlantı hatası: <Fault 1: 'Traceback (most recent call last):\n  File "/usr/lib/python3/dist-packages/odoo/modules/registry.py", line 61, in __new__\n    return cls.registries[db_name]\n  File "/usr/lib/python3/dist-packages/odoo/tools/func.py", line 71, in wrapper\n    return func(self, *args, **kwargs)\n  File "/usr/lib/python3/dist-packages/odoo/tools/lru.py", line 34, in __getitem__\n    a = self.d[obj]\nKeyError: \'zuhalmuzik\'\n\nDuring handling of the above exception, another exception occurred:\n\nTraceback (most recent call last):\n  File "/usr/lib/python3/dist-packages/odoo/addons/base/controllers/rpc.py", line 93, in xmlrpc_2\n    response = self._xmlrpc(service)\n  File "/usr/lib/python3/dist-packages/odoo/addons/base/controllers/rpc.py", line 73, in _xmlrpc\n    result = dispatch_rpc(service, method, params)\n  File "/usr/lib/python3/dist-packages/odoo/http.py", line 141, in dispatch_rpc\n    result = dispatch(method, params)\n  File "/usr/lib/python3/dist-packages/odoo/service/common.py", line 56, in dispatch\n    return g[exp_method_name](*params)\n  File "/usr/lib/python3/dist-packages/odoo/service/common.py", line 25, in exp_authenticate\n    res_users = odoo.registry(db)[\'res.users\']\n  File "/usr/lib/python3/dist-packages/odoo/__init__.py", line 104, in registry\n    return modules.registry.Registry(database_name)\n  File "/usr/lib/python3/dist-packages/odoo/modules/registry.py", line 63, in __new__\n    return cls.new(db_name)\n  File "/usr/lib/python3/dist-packages/odoo/modules/registry.py", line 75, in new\n    registry.init(db_name)\n  File "/usr/lib/python3/dist-packages/odoo/modules/registry.py", line 151, in init\n    with closing(self.cursor()) as cr:\n  File "/usr/lib/python3/dist-packages/odoo/modules/registry.py", line 728, in cursor\n    return self._db.cursor()\n  File "/usr/lib/python3/dist-packages/odoo/sql_db.py", line 742, in cursor\n    return Cursor(self.__pool, self.__dbname, self.__dsn, serialized=serialized)\n  File "/usr/lib/python3/dist-packages/odoo/sql_db.py", line 259, in __init__\n    self._cnx = pool.borrow(dsn)\n  File "/usr/lib/python3/dist-packages/odoo/sql_db.py", line 603, in _locked\n    return fun(self, *args, **kwargs)\n  File "/usr/lib/python3/dist-packages/odoo/sql_db.py", line 669, in borrow\n    result = psycopg2.connect(\n  File "/usr/lib/python3/dist-packages/psycopg2/__init__.py", line 122, in connect\n    conn = _connect(dsn, connection_factory=connection_factory, **kwasync)\npsycopg2.OperationalError: connection to server on socket "/var/run/postgresql/.s.PGSQL.5432" failed: FATAL:  database "zuhalmuzik" does not exist\n\n'>
[2025-10-17 21:39:16] ============================================================
[2025-10-17 21:39:16] 🚀 Odoo Veri Güncelleme Script'i Başlatıldı
[2025-10-17 21:39:16] ============================================================
[2025-10-17 21:39:16] 🔌 Odoo'ya bağlanılıyor...
[2025-10-17 21:39:16] 📌 Odoo Versiyonu: 15.0-20240120
[2025-10-17 21:39:16] ❌ HATA: Odoo bağlantı hatası: <Fault 1: 'Traceback (most recent call last):\n  File "/usr/lib/python3/dist-packages/odoo/modules/registry.py", line 61, in __new__\n    return cls.registries[db_name]\n  File "/usr/lib/python3/dist-packages/odoo/tools/func.py", line 71, in wrapper\n    return func(self, *args, **kwargs)\n  File "/usr/lib/python3/dist-packages/odoo/tools/lru.py", line 34, in __getitem__\n    a = self.d[obj]\nKeyError: \'zuhalmuzik\'\n\nDuring handling of the above exception, another exception occurred:\n\nTraceback (most recent call last):\n  File "/usr/lib/python3/dist-packages/odoo/addons/base/controllers/rpc.py", line 93, in xmlrpc_2\n    response = self._xmlrpc(service)\n  File "/usr/lib/python3/dist-packages/odoo/addons/base/controllers/rpc.py", line 73, in _xmlrpc\n    result = dispatch_rpc(service, method, params)\n  File "/usr/lib/python3/dist-packages/odoo/http.py", line 141, in dispatch_rpc\n    result = dispatch(method, params)\n  File "/usr/lib/python3/dist-packages/odoo/service/common.py", line 56, in dispatch\n    return g[exp_method_name](*params)\n  File "/usr/lib/python3/dist-packages/odoo/service/common.py", line 25, in exp_authenticate\n    res_users = odoo.registry(db)[\'res.users\']\n  File "/usr/lib/python3/dist-packages/odoo/__init__.py", line 104, in registry\n    return modules.registry.Registry(database_name)\n  File "/usr/lib/python3/dist-packages/odoo/modules/registry.py", line 63, in __new__\n    return cls.new(db_name)\n  File "/usr/lib/python3/dist-packages/odoo/modules/registry.py", line 75, in new\n    registry.init(db_name)\n  File "/usr/lib/python3/dist-packages/odoo/modules/registry.py", line 151, in init\n    with closing(self.cursor()) as cr:\n  File "/usr/lib/python3/dist-packages/odoo/modules/registry.py", line 728, in cursor\n    return self._db.cursor()\n  File "/usr/lib/python3/dist-packages/odoo/sql_db.py", line 742, in cursor\n    return Cursor(self.__pool, self.__dbname, self.__dsn, serialized=serialized)\n  File "/usr/lib/python3/dist-packages/odoo/sql_db.py", line 259, in __init__\n    self._cnx = pool.borrow(dsn)\n  File "/usr/lib/python3/dist-packages/odoo/sql_db.py", line 603, in _locked\n    return fun(self, *args, **kwargs)\n  File "/usr/lib/python3/dist-packages/odoo/sql_db.py", line 669, in borrow\n    result = psycopg2.connect(\n  File "/usr/lib/python3/dist-packages/psycopg2/__init__.py", line 122, in connect\n    conn = _connect(dsn, connection_factory=connection_factory, **kwasync)\npsycopg2.OperationalError: connection to server on socket "/var/run/postgresql/.s.PGSQL.5432" failed: FATAL:  database "zuhalmuzik" does not exist\n\n'>
[2025-10-17 21:39:21] ============================================================
[2025-10-17 21:39:21] 🚀 Odoo Veri Güncelleme Script'i Başlatıldı
[2025-10-17 21:39:21] ============================================================
[2025-10-17 21:39:21] 🔌 Odoo'ya bağlanılıyor...
[2025-10-17 21:39:21] 📌 Odoo Versiyonu: 15.0-20240120
[2025-10-17 21:39:21] ❌ HATA: Odoo bağlantı hatası: <Fault 1: 'Traceback (most recent call last):\n  File "/usr/lib/python3/dist-packages/odoo/modules/registry.py", line 61, in __new__\n    return cls.registries[db_name]\n  File "/usr/lib/python3/dist-packages/odoo/tools/func.py", line 71, in wrapper\n    return func(self, *args, **kwargs)\n  File "/usr/lib/python3/dist-packages/odoo/tools/lru.py", line 34, in __getitem__\n    a = self.d[obj]\nKeyError: \'zuhalmuzik\'\n\nDuring handling of the above exception, another exception occurred:\n\nTraceback (most recent call last):\n  File "/usr/lib/python3/dist-packages/odoo/addons/base/controllers/rpc.py", line 93, in xmlrpc_2\n    response = self._xmlrpc(service)\n  File "/usr/lib/python3/dist-packages/odoo/addons/base/controllers/rpc.py", line 73, in _xmlrpc\n    result = dispatch_rpc(service, method, params)\n  File "/usr/lib/python3/dist-packages/odoo/http.py", line 141, in dispatch_rpc\n    result = dispatch(method, params)\n  File "/usr/lib/python3/dist-packages/odoo/service/common.py", line 56, in dispatch\n    return g[exp_method_name](*params)\n  File "/usr/lib/python3/dist-packages/odoo/service/common.py", line 25, in exp_authenticate\n    res_users = odoo.registry(db)[\'res.users\']\n  File "/usr/lib/python3/dist-packages/odoo/__init__.py", line 104, in registry\n    return modules.registry.Registry(database_name)\n  File "/usr/lib/python3/dist-packages/odoo/modules/registry.py", line 63, in __new__\n    return cls.new(db_name)\n  File "/usr/lib/python3/dist-packages/odoo/modules/registry.py", line 75, in new\n    registry.init(db_name)\n  File "/usr/lib/python3/dist-packages/odoo/modules/registry.py", line 151, in init\n    with closing(self.cursor()) as cr:\n  File "/usr/lib/python3/dist-packages/odoo/modules/registry.py", line 728, in cursor\n    return self._db.cursor()\n  File "/usr/lib/python3/dist-packages/odoo/sql_db.py", line 742, in cursor\n    return Cursor(self.__pool, self.__dbname, self.__dsn, serialized=serialized)\n  File "/usr/lib/python3/dist-packages/odoo/sql_db.py", line 259, in __init__\n    self._cnx = pool.borrow(dsn)\n  File "/usr/lib/python3/dist-packages/odoo/sql_db.py", line 603, in _locked\n    return fun(self, *args, **kwargs)\n  File "/usr/lib/python3/dist-packages/odoo/sql_db.py", line 669, in borrow\n    result = psycopg2.connect(\n  File "/usr/lib/python3/dist-packages/psycopg2/__init__.py", line 122, in connect\n    conn = _connect(dsn, connection_factory=connection_factory, **kwasync)\npsycopg2.OperationalError: connection to server on socket "/var/run/postgresql/.s.PGSQL.5432" failed: FATAL:  database "zuhalmuzik" does not exist\n\n'>
[2025-10-17 21:43:12] ============================================================
[2025-10-17 21:43:12] 🚀 Odoo Veri Güncelleme Script'i Başlatıldı
[2025-10-17 21:43:12] ============================================================
[2025-10-17 21:43:12] 🔌 Odoo'ya bağlanılıyor...
[2025-10-17 21:43:12] 📌 Odoo Versiyonu: 15.0-20240120
[2025-10-17 21:43:13] ❌ HATA: Odoo bağlantı hatası: <Fault 1: 'Traceback (most recent call last):\n  File "/usr/lib/python3/dist-packages/odoo/modules/registry.py", line 61, in __new__\n    return cls.registries[db_name]\n  File "/usr/lib/python3/dist-packages/odoo/tools/func.py", line 71, in wrapper\n    return func(self, *args, **kwargs)\n  File "/usr/lib/python3/dist-packages/odoo/tools/lru.py", line 34, in __getitem__\n    a = self.d[obj]\nKeyError: \'zuhalmuzik\'\n\nDuring handling of the above exception, another exception occurred:\n\nTraceback (most recent call last):\n  File "/usr/lib/python3/dist-packages/odoo/addons/base/controllers/rpc.py", line 93, in xmlrpc_2\n    response = self._xmlrpc(service)\n  File "/usr/lib/python3/dist-packages/odoo/addons/base/controllers/rpc.py", line 73, in _xmlrpc\n    result = dispatch_rpc(service, method, params)\n  File "/usr/lib/python3/dist-packages/odoo/http.py", line 141, in dispatch_rpc\n    result = dispatch(method, params)\n  File "/usr/lib/python3/dist-packages/odoo/service/common.py", line 56, in dispatch\n    return g[exp_method_name](*params)\n  File "/usr/lib/python3/dist-packages/odoo/service/common.py", line 25, in exp_authenticate\n    res_users = odoo.registry(db)[\'res.users\']\n  File "/usr/lib/python3/dist-packages/odoo/__init__.py", line 104, in registry\n    return modules.registry.Registry(database_name)\n  File "/usr/lib/python3/dist-packages/odoo/modules/registry.py", line 63, in __new__\n    return cls.new(db_name)\n  File "/usr/lib/python3/dist-packages/odoo/modules/registry.py", line 75, in new\n    registry.init(db_name)\n  File "/usr/lib/python3/dist-packages/odoo/modules/registry.py", line 151, in init\n    with closing(self.cursor()) as cr:\n  File "/usr/lib/python3/dist-packages/odoo/modules/registry.py", line 728, in cursor\n    return self._db.cursor()\n  File "/usr/lib/python3/dist-packages/odoo/sql_db.py", line 742, in cursor\n    return Cursor(self.__pool, self.__dbname, self.__dsn, serialized=serialized)\n  File "/usr/lib/python3/dist-packages/odoo/sql_db.py", line 259, in __init__\n    self._cnx = pool.borrow(dsn)\n  File "/usr/lib/python3/dist-packages/odoo/sql_db.py", line 603, in _locked\n    return fun(self, *args, **kwargs)\n  File "/usr/lib/python3/dist-packages/odoo/sql_db.py", line 669, in borrow\n    result = psycopg2.connect(\n  File "/usr/lib/python3/dist-packages/psycopg2/__init__.py", line 122, in connect\n    conn = _connect(dsn, connection_factory=connection_factory, **kwasync)\npsycopg2.OperationalError: connection to server on socket "/var/run/postgresql/.s.PGSQL.5432" failed: FATAL:  database "zuhalmuzik" does not exist\n\n'>
[2025-10-17 22:41:48] ============================================================
[2025-10-17 22:41:48] 🚀 Odoo Veri Güncelleme Script'i Başlatıldı
[2025-10-17 22:41:48] ============================================================
[2025-10-17 22:41:48] 🔌 Odoo'ya bağlanılıyor...
[2025-10-17 22:41:48] 📌 Odoo Versiyonu: 15.0-20240120
[2025-10-17 22:41:48] ❌ HATA: Odoo bağlantı hatası: <Fault 1: 'Traceback (most recent call last):\n  File "/usr/lib/python3/dist-packages/odoo/modules/registry.py", line 61, in __new__\n    return cls.registries[db_name]\n  File "/usr/lib/python3/dist-packages/odoo/tools/func.py", line 71, in wrapper\n    return func(self, *args, **kwargs)\n  File "/usr/lib/python3/dist-packages/odoo/tools/lru.py", line 34, in __getitem__\n    a = self.d[obj]\nKeyError: \'zuhalmuzik\'\n\nDuring handling of the above exception, another exception occurred:\n\nTraceback (most recent call last):\n  File "/usr/lib/python3/dist-packages/odoo/addons/base/controllers/rpc.py", line 93, in xmlrpc_2\n    response = self._xmlrpc(service)\n  File "/usr/lib/python3/dist-packages/odoo/addons/base/controllers/rpc.py", line 73, in _xmlrpc\n    result = dispatch_rpc(service, method, params)\n  File "/usr/lib/python3/dist-packages/odoo/http.py", line 141, in dispatch_rpc\n    result = dispatch(method, params)\n  File "/usr/lib/python3/dist-packages/odoo/service/common.py", line 56, in dispatch\n    return g[exp_method_name](*params)\n  File "/usr/lib/python3/dist-packages/odoo/service/common.py", line 25, in exp_authenticate\n    res_users = odoo.registry(db)[\'res.users\']\n  File "/usr/lib/python3/dist-packages/odoo/__init__.py", line 104, in registry\n    return modules.registry.Registry(database_name)\n  File "/usr/lib/python3/dist-packages/odoo/modules/registry.py", line 63, in __new__\n    return cls.new(db_name)\n  File "/usr/lib/python3/dist-packages/odoo/modules/registry.py", line 75, in new\n    registry.init(db_name)\n  File "/usr/lib/python3/dist-packages/odoo/modules/registry.py", line 151, in init\n    with closing(self.cursor()) as cr:\n  File "/usr/lib/python3/dist-packages/odoo/modules/registry.py", line 728, in cursor\n    return self._db.cursor()\n  File "/usr/lib/python3/dist-packages/odoo/sql_db.py", line 742, in cursor\n    return Cursor(self.__pool, self.__dbname, self.__dsn, serialized=serialized)\n  File "/usr/lib/python3/dist-packages/odoo/sql_db.py", line 259, in __init__\n    self._cnx = pool.borrow(dsn)\n  File "/usr/lib/python3/dist-packages/odoo/sql_db.py", line 603, in _locked\n    return fun(self, *args, **kwargs)\n  File "/usr/lib/python3/dist-packages/odoo/sql_db.py", line 669, in borrow\n    result = psycopg2.connect(\n  File "/usr/lib/python3/dist-packages/psycopg2/__init__.py", line 122, in connect\n    conn = _connect(dsn, connection_factory=connection_factory, **kwasync)\npsycopg2.OperationalError: connection to server on socket "/var/run/postgresql/.s.PGSQL.5432" failed: FATAL:  database "zuhalmuzik" does not exist\n\n'>
